#VRML_SIM R2021a utf8
PROTO delta [
    field  SFVec3f     translation     0 0 0
    field  SFRotation  rotation        1 0 0 0 
    field  SFString    name            "delta"  # Is `Robot.name`.
    field  SFString    controller      "void"      # Is `Robot.controller`.
    field  MFString    controllerArgs  []          # Is `Robot.controllerArgs`.
    field  SFString    customData      ""          # Is `Robot.customData`.
    field  SFBool      supervisor      FALSE       # Is `Robot.supervisor`.
    field  SFBool      synchronization TRUE        # Is `Robot.synchronization`.
    field  SFBool      selfCollision   FALSE       # Is `Robot.selfCollision`.
]
{
    Robot {
        translation 0 1.00 0
            children [
            Solid {
                rotation 1 0 0 -1.57
                    children [
                    Solid {
                        rotation 1 0 0 1.57
                            children [
                            Shape {
                                appearance PBRAppearance {
                                }
                                geometry Cylinder {
                                    height 0.02
                                        radius 0.15
                                }
                            }
                            ]
                                name "upper_platform"
                                boundingObject Cylinder {
                                    height 0.02
                                        radius 0.15
                                }
                            physics Physics {
                                mass 4
                                    centerOfMass [
                                    0 0 0
                                    ]
                            }
                    }
                Transform {
                    rotation 0 0 1 0
                        children [
                        Solid {
                            translation 0.13 0 0
                                children [
                                Shape {
                                    appearance PBRAppearance {
                                    }
                                    geometry Cylinder {
                                        height 0.03
                                            radius 0.025
                                    }
                                }
                            HingeJoint {
                                jointParameters HingeJointParameters {
                                    position 2
                                        axis 0 1 0
                                }
                                device [
                                    PositionSensor {
                                        name "delta_arm_0_encoder"
                                    }
                                RotationalMotor {
                                    name "delta_arm_0_motor"
                                        maxTorque 4000
                                }
                                ]
                                    endPoint DEF ARM_0 Solid {
                                        translation -0.03329174692377138 0 -0.07274379414605456
                                            rotation 0 1 0 1.9999999999999998
                                            children [
                                            Transform {
                                                translation 0.08 -0.015 0
                                                    children [
                                                    Hinge2Joint {
                                                        jointParameters HingeJointParameters {
                                                            position -2.42
                                                                axis 0 1 0
                                                        }
                                                        jointParameters2 JointParameters {
                                                            minStop -1.5
                                                                maxStop 1.5
                                                        }
                                                        endPoint Solid {
                                                            translation 0.16435600925621546 0 0.07339688155072266
                                                                rotation 0 -0.9999999999999999 0 0.4199999999999987
                                                                children [
                                                                Transform {
                                                                    translation 0.18 0 0
                                                                        children [
                                                                        Hinge2Joint {
                                                                            jointParameters HingeJointParameters {
                                                                                position -3.14
                                                                                    axis 0 1 0
                                                                            }
                                                                            jointParameters2 JointParameters {
                                                                                minStop -1.5
                                                                                    maxStop 1.5
                                                                            }
                                                                            endPoint Solid {
                                                                                translation -0.0001433386867368857 0.015 -0.059999828783263084
                                                                                    rotation -0.5762774369883852 -0.578115985622625 0.5776557995776366 4.187869343793437
                                                                                    children [
                                                                                    Shape {
                                                                                        appearance PBRAppearance {
                                                                                        }
                                                                                        geometry Cylinder {
                                                                                            height 0.01
                                                                                                radius 0.06
                                                                                        }
                                                                                    }
                                                                                    ]
                                                                                        name "lower_platform"
                                                                                        boundingObject Cylinder {
                                                                                            height 0.01
                                                                                                radius 0.06
                                                                                        }
                                                                                    physics Physics {
                                                                                        mass 2
                                                                                    }
                                                                            }
                                                                        }
                                                                    ]
                                                                }
                                                            Shape {
                                                                appearance PBRAppearance {
                                                                }
                                                                geometry Box {
                                                                    size 0.36 0.01 0.01
                                                                }
                                                            }
                                                            ]
                                                                name "arm_0_l0_leg_link"
                                                                boundingObject Shape {
                                                                    appearance PBRAppearance {
                                                                    }
                                                                    geometry Box {
                                                                        size 0.36 0.01 0.01
                                                                    }
                                                                }
                                                            physics Physics {
                                                                mass 1.5
                                                            }
                                                        }
                                                    }
                                                ]
                                            }
                                        Transform {
                                            translation 0.08 0.015 0
                                                children [
                                                Hinge2Joint {
                                                    jointParameters HingeJointParameters {
                                                        position -2.42
                                                            axis 0 1 0
                                                    }
                                                    jointParameters2 JointParameters {
                                                        minStop -1.5
                                                            maxStop 1.5
                                                    }
                                                    endPoint Solid {
                                                        translation 0.16435600925621546 0 0.07339688155072266
                                                            rotation 0 -0.9999999999999999 0 0.4199999999999987
                                                            children [
                                                            Transform {
                                                                translation 0.18 0 0
                                                                    children [
                                                                    Hinge2Joint {
                                                                        jointParameters HingeJointParameters {
                                                                            axis 0 1 0
                                                                        }
                                                                        jointParameters2 JointParameters {
                                                                            minStop -1.5
                                                                                maxStop 1.5
                                                                        }
                                                                        endPoint SolidReference {
                                                                            solidName "lower_platform"
                                                                        }
                                                                    }
                                                                    ]
                                                            }
                                                        Shape {
                                                            appearance PBRAppearance {
                                                            }
                                                            geometry Box {
                                                                size 0.36 0.01 0.01
                                                            }
                                                        }
                                                        ]
                                                            name "arm_0_l1_leg_link"
                                                            boundingObject Shape {
                                                                appearance PBRAppearance {
                                                                }
                                                                geometry Box {
                                                                    size 0.36 0.01 0.01
                                                                }
                                                            }
                                                        physics Physics {
                                                            mass 1.5
                                                        }
                                                    }
                                                }
                                            ]
                                        }
                                        Shape {
                                            appearance PBRAppearance {
                                            }
                                            geometry Box {
                                                size 0.16 0.03 0.03
                                            }
                                        }
                                        ]
                                            name "arm_0_upper_leg_link"
                                            boundingObject Shape {
                                                appearance PBRAppearance {
                                                }
                                                geometry Box {
                                                    size 0.16 0.03 0.03
                                                }
                                            }
                                        physics Physics {
                                            mass 1.1
                                        }
                                    }
                            }
                            ]
                                name "arm_0"
                                boundingObject Cylinder {
                                    height 0.03
                                        radius 0.025
                                }
                            physics Physics {
                                mass 0.02
                            }
                        }
                    ]
                }
                Transform {
                    rotation 0 0 1 -2.09
                        children [
                        Solid {
                            translation 0.13 0 0
                                children [
                                Shape {
                                    appearance PBRAppearance {
                                    }
                                    geometry Cylinder {
                                        height 0.03
                                            radius 0.025
                                    }
                                }
                            HingeJoint {
                                jointParameters HingeJointParameters {
                                    position 2
                                        axis 0 1 0
                                }
                                device [
                                    PositionSensor {
                                        name "delta_arm_1_encoder"
                                    }
                                RotationalMotor {
                                    name "delta_arm_1_motor"
                                        maxTorque 4000
                                }
                                ]
                                    endPoint DEF ARM_1 Solid {
                                        translation -0.03329174692377138 0 -0.07274379414605456
                                            rotation 0 1 0 1.9999999999999998
                                            children [
                                            Transform {
                                                translation 0.08 -0.015 0
                                                    children [
                                                    Hinge2Joint {
                                                        jointParameters HingeJointParameters {
                                                            position -2.42
                                                                axis 0 1 0
                                                        }
                                                        jointParameters2 JointParameters {
                                                            minStop -1.5
                                                                maxStop 1.5
                                                        }
                                                        endPoint Solid {
                                                            translation 0.16435600925621546 0 0.07339688155072266
                                                                rotation 0 -0.9999999999999999 0 0.4199999999999987
                                                                children [
                                                                Transform {
                                                                    translation 0.18 0 0
                                                                        children [
                                                                        Hinge2Joint {
                                                                            jointParameters HingeJointParameters {
                                                                                axis 0 1 0
                                                                            }
                                                                            jointParameters2 JointParameters {
                                                                                minStop -1.5
                                                                                    maxStop 1.5
                                                                            }
                                                                            endPoint SolidReference {
                                                                                solidName "lower_platform"
                                                                            }
                                                                        }
                                                                        ]
                                                                }
                                                            Shape {
                                                                appearance PBRAppearance {
                                                                }
                                                                geometry Box {
                                                                    size 0.36 0.01 0.01
                                                                }
                                                            }
                                                            ]
                                                                name "arm_1_l0_leg_link"
                                                                boundingObject Shape {
                                                                    appearance PBRAppearance {
                                                                    }
                                                                    geometry Box {
                                                                        size 0.36 0.01 0.01
                                                                    }
                                                                }
                                                            physics Physics {
                                                                mass 1.5
                                                            }
                                                        }
                                                    }
                                                ]
                                            }
                                        Transform {
                                            translation 0.08 0.015 0
                                                children [
                                                Hinge2Joint {
                                                    jointParameters HingeJointParameters {
                                                        position -2.42
                                                            axis 0 1 0
                                                    }
                                                    jointParameters2 JointParameters {
                                                        minStop -1.5
                                                            maxStop 1.5
                                                    }
                                                    endPoint Solid {
                                                        translation 0.16435600925621546 0 0.07339688155072266
                                                            rotation 0 -0.9999999999999999 0 0.4199999999999987
                                                            children [
                                                            Transform {
                                                                translation 0.18 0 0
                                                                    children [
                                                                    Hinge2Joint {
                                                                        jointParameters HingeJointParameters {
                                                                            axis 0 1 0
                                                                        }
                                                                        jointParameters2 JointParameters {
                                                                            minStop -1.5
                                                                                maxStop 1.5
                                                                        }
                                                                        endPoint SolidReference {
                                                                            solidName "lower_platform"
                                                                        }
                                                                    }
                                                                    ]
                                                            }
                                                        Shape {
                                                            appearance PBRAppearance {
                                                            }
                                                            geometry Box {
                                                                size 0.36 0.01 0.01
                                                            }
                                                        }
                                                        ]
                                                            name "arm_1_l1_leg_link"
                                                            boundingObject Shape {
                                                                appearance PBRAppearance {
                                                                }
                                                                geometry Box {
                                                                    size 0.36 0.01 0.01
                                                                }
                                                            }
                                                        physics Physics {
                                                            mass 1.5
                                                        }
                                                    }
                                                }
                                            ]
                                        }
                                        Shape {
                                            appearance PBRAppearance {
                                            }
                                            geometry Box {
                                                size 0.16 0.03 0.03
                                            }
                                        }
                                        ]
                                            name "arm_1_upper_leg_link"
                                            boundingObject Shape {
                                                appearance PBRAppearance {
                                                }
                                                geometry Box {
                                                    size 0.16 0.03 0.03
                                                }
                                            }
                                        physics Physics {
                                            mass 1.1
                                        }
                                    }
                            }
                            ]
                                name "arm_1"
                                boundingObject Cylinder {
                                    height 0.03
                                        radius 0.025
                                }
                            physics Physics {
                                mass 0.02
                            }
                        }
                    ]
                }
                Transform {
                    rotation 0 0 1 2.09
                        children [
                        Solid {
                            translation 0.13 0 0
                                children [
                                Shape {
                                    appearance PBRAppearance {
                                    }
                                    geometry Cylinder {
                                        height 0.03
                                            radius 0.025
                                    }
                                }
                            HingeJoint {
                                jointParameters HingeJointParameters {
                                    position 2
                                        axis 0 1 0
                                }
                                device [
                                    PositionSensor {
                                        name "delta_arm_2_encoder"
                                    }
                                RotationalMotor {
                                    name "delta_arm_2_motor"
                                        maxTorque 4000
                                }
                                ]
                                    endPoint DEF ARM_2 Solid {
                                        translation -0.03329174692377138 0 -0.07274379414605456
                                            rotation 0 1 0 1.9999999999999998
                                            children [
                                            Transform {
                                                translation 0.08 -0.015 0
                                                    children [
                                                    Hinge2Joint {
                                                        jointParameters HingeJointParameters {
                                                            position -2.42
                                                                axis 0 1 0
                                                        }
                                                        jointParameters2 JointParameters {
                                                            minStop -1.5
                                                                maxStop 1.5
                                                        }
                                                        endPoint Solid {
                                                            translation 0.16435600925621546 0 0.07339688155072266
                                                                rotation 0 -0.9999999999999999 0 0.4199999999999987
                                                                children [
                                                                Transform {
                                                                    translation 0.18 0 0
                                                                        children [
                                                                        Hinge2Joint {
                                                                            jointParameters HingeJointParameters {
                                                                                axis 0 1 0
                                                                            }
                                                                            jointParameters2 JointParameters {
                                                                                minStop -1.5
                                                                                    maxStop 1.5
                                                                            }
                                                                            endPoint SolidReference {
                                                                                solidName "lower_platform"
                                                                            }
                                                                        }
                                                                        ]
                                                                }
                                                            Shape {
                                                                appearance PBRAppearance {
                                                                }
                                                                geometry Box {
                                                                    size 0.36 0.01 0.01
                                                                }
                                                            }
                                                            ]
                                                                name "arm_2_l0_leg_link"
                                                                boundingObject Shape {
                                                                    appearance PBRAppearance {
                                                                    }
                                                                    geometry Box {
                                                                        size 0.36 0.01 0.01
                                                                    }
                                                                }
                                                            physics Physics {
                                                                mass 1.5
                                                            }
                                                        }
                                                    }
                                                ]
                                            }
                                        Transform {
                                            translation 0.08 0.015 0
                                                children [
                                                Hinge2Joint {
                                                    jointParameters HingeJointParameters {
                                                        position -2.42
                                                            axis 0 1 0
                                                    }
                                                    jointParameters2 JointParameters {
                                                        minStop -1.5
                                                            maxStop 1.5
                                                    }
                                                    endPoint Solid {
                                                        translation 0.16435600925621546 0 0.07339688155072266
                                                            rotation 0 -0.9999999999999999 0 0.4199999999999987
                                                            children [
                                                            Transform {
                                                                translation 0.18 0 0
                                                                    children [
                                                                    Hinge2Joint {
                                                                        jointParameters HingeJointParameters {
                                                                            axis 0 1 0
                                                                        }
                                                                        jointParameters2 JointParameters {
                                                                            minStop -1.5
                                                                                maxStop 1.5
                                                                        }
                                                                        endPoint SolidReference {
                                                                            solidName "lower_platform"
                                                                        }
                                                                    }
                                                                    ]
                                                            }
                                                        Shape {
                                                            appearance PBRAppearance {
                                                            }
                                                            geometry Box {
                                                                size 0.36 0.01 0.01
                                                            }
                                                        }
                                                        ]
                                                            name "arm_2_l2_leg_link"
                                                            boundingObject Shape {
                                                                appearance PBRAppearance {
                                                                }
                                                                geometry Box {
                                                                    size 0.36 0.01 0.01
                                                                }
                                                            }
                                                        physics Physics {
                                                            mass 1.5
                                                        }
                                                    }
                                                }
                                            ]
                                        }
                                        Shape {
                                            appearance PBRAppearance {
                                            }
                                            geometry Box {
                                                size 0.16 0.03 0.03
                                            }
                                        }
                                        ]
                                            name "arm_2_upper_leg_link"
                                            boundingObject Shape {
                                                appearance PBRAppearance {
                                                }
                                                geometry Box {
                                                    size 0.16 0.03 0.03
                                                }
                                            }
                                        physics Physics {
                                            mass 1.1
                                        }
                                    }
                            }
                            ]
                                name "arm_2"
                                boundingObject Cylinder {
                                    height 0.03
                                        radius 0.025
                                }
                            physics Physics {
                                mass 0.02
                            }
                        }
                    ]
                }
                ]
                    name "grasper_base"
                    boundingObject Sphere {
                        radius 0.005
                    }
                physics Physics {
                    mass 0.02
                }
            }
        ]
            name "delta_top"
            controller "<extern>"
            controllerArgs [
            ""
            ]
    }

}
